Workbook

Sheet README
A1: Purse Maison – Mock Historical Data (from client catalog)
A2: Built from the client's Sample_Data.xlsx (1,525 items). Client allowed it to be used and modified as mock history.
A4: What is REAL (from the client file)
A5: Barcode, brand, full item name, price. Model, colour, hardware, date code/stamp and size are parsed from the item name.
A6: What is GENERATED (mock) – shaded cream in every sheet
A7: All dates, consignors, buyers, condition notes, accessories, inquiry channel, sale type, layaway payments, and which items sold.
A8: Consignor and buyer names are fictional; emails use example.com and phone numbers are random.
A10: How the data is split
A11: Sold Items – past sales from Oct 2023 to Oct 13, 2026 (36 full months + October so far), imported as full item + listing + sale records.
A12: Current Stock – items listed now (Available) or on an active layaway (Reserved).
A13: Closed Items – rejected or failed authentication, never listed.
A14: Historical Sales – sales of items priced in the markup-rule gap (₱20,001–₱49,999, or ₱49,001–₱49,999 for shoes/wallets).
... A38: Excluded (no price): 1

Sheet Monthly Summary
A1: Month | B1: Full-Record Sales (count) | C1: Full-Record Revenue | D1: Historical Sales (count) | E1: Historical Revenue | F1: Total Revenue
A2: 45200 | B2: =COUNTIFS('Sold Items'!$R$2:$R$720,">="&A2,'Sold Items'!$R$2:$R$720,"<"&EDATE(A2,1)) -> 12 | C2: =SUMIFS('Sold Items'!$H$2:$H$720,'Sold Items'!$R$2:$R$720,">="&A2,'Sold Items'!$R$2:$R$720,"<"&EDATE(A2,1)) -> 1808600 | D2: =COUNTIFS('Historical Sales'!$A$2:$A$243,">="&A2,'Historical Sales'!$A$2:$A$243,"<"&EDATE(A2,1)) -> 2 | E2: =SUMIFS('Historical Sales'!$F$2:$F$243,'Historical Sales'!$A$2:$A$243,">="&A2,'Historical Sales'!$A$2:$A$243,"<"&EDATE(A2,1)) -> 82600 | F2: =C2+E2 -> 1891200
A3: 45231 | B3: =COUNTIFS('Sold Items'!$R$2:$R$720,">="&A3,'Sold Items'!$R$2:$R$720,"<"&EDATE(A3,1)) -> 15 | C3: =SUMIFS('Sold Items'!$H$2:$H$720,'Sold Items'!$R$2:$R$720,">="&A3,'Sold Items'!$R$2:$R$720,"<"&EDATE(A3,1)) -> 2189300 | D3: =COUNTIFS('Historical Sales'!$A$2:$A$243,">="&A3,'Historical Sales'!$A$2:$A$243,"<"&EDATE(A3,1)) -> 3 | E3: =SUMIFS('Historical Sales'!$F$2:$F$243,'Historical Sales'!$A$2:$A$243,">="&A3,'Historical Sales'!$A$2:$A$243,"<"&EDATE(A3,1)) -> 94100 | F3: =C3+E3 -> 2283400
A4: 45261 | B4: =COUNTIFS('Sold Items'!$R$2:$R$720,">="&A4,'Sold Items'!$R$2:$R$720,"<"&EDATE(A4,1)) -> 28 | C4: =SUMIFS('Sold Items'!$H$2:$H$720,'Sold Items'!$R$2:$R$720,">="&A4,'Sold Items'!$R$2:$R$720,"<"&EDATE(A4,1)) -> 3737900 | D4: =COUNTIFS('Historical Sales'!$A$2:$A$243,">="&A4,'Historical Sales'!$A$2:$A$243,"<"&EDATE(A4,1)) -> 8 | E4: =SUMIFS('Historical Sales'!$F$2:$F$243,'Historical Sales'!$A$2:$A$243,">="&A4,'Historical Sales'!$A$2:$A$243,"<"&EDATE(A4,1)) -> 311600 | F4: =C4+E4 -> 4049500
A5: 45292 | B5: =COUNTIFS('Sold Items'!$R$2:$R$720,">="&A5,'Sold Items'!$R$2:$R$720,"<"&EDATE(A5,1)) -> 18 | C5: =SUMIFS('Sold Items'!$H$2:$H$720,'Sold Items'!$R$2:$R$720,">="&A5,'Sold Items'!$R$2:$R$720,"<"&EDATE(A5,1)) -> 2628800 | D5: =COUNTIFS('Historical Sales'!$A$2:$A$243,">="&A5,'Historical Sales'!$A$2:$A$243,"<"&EDATE(A5,1)) -> 3 | E5: =SUMIFS('Historical Sales'!$F$2:$F$243,'Historical Sales'!$A$2:$A$243,">="&A5,'Historical Sales'!$A$2:$A$243,"<"&EDATE(A5,1)) -> 117500 | F5: =C5+E5 -> 2746300
A6: 45323 | B6: =COUNTIFS('Sold Items'!$R$2:$R$720,">="&A6,'Sold Items'!$R$2:$R$720,"<"&EDATE(A6,1)) -> 13 | C6: =SUMIFS('Sold Items'!$H$2:$H$720,'Sold Items'!$R$2:$R$720,">="&A6,'Sold Items'!$R$2:$R$720,"<"&EDATE(A6,1)) -> 1957400 | D6: =COUNTIFS('Historical Sales'!$A$2:$A$243,">="&A6,'Historical Sales'!$A$2:$A$243,"<"&EDATE(A6,1)) -> 4 | E6: =SUMIFS('Historical Sales'!$F$2:$F$243,'Historical Sales'!$A$2:$A$243,">="&A6,'Historical Sales'!$A$2:$A$243,"<"&EDATE(A6,1)) -> 158400 | F6: =C6+E6 -> 2115800
A7: 45352 | B7: =COUNTIFS('Sold Items'!$R$2:$R$720,">="&A7,'Sold Items'!$R$2:$R$720,"<"&EDATE(A7,1)) -> 17 | C7: =SUMIFS('Sold Items'!$H$2:$H$720,'Sold Items'!$R$2:$R$720,">="&A7,'Sold Items'!$R$2:$R$720,"<"&EDATE(A7,1)) -> 2956400 | D7: =COUNTIFS('Historical Sales'!$A$2:$A$243,">="&A7,'Historical Sales'!$A$2:$A$243,"<"&EDATE(A7,1)) -> 6 | E7: =SUMIFS('Historical Sales'!$F$2:$F$243,'Historical Sales'!$A$2:$A$243,">="&A7,'Historical Sales'!$A$2:$A$243,"<"&EDATE(A7,1)) -> 213300 | F7: =C7+E7 -> 3169700
A8: 45383 | B8: =COUNTIFS('Sold Items'!$R$2:$R$720,">="&A8,'Sold Items'!$R$2:$R$720,"<"&EDATE(A8,1)) -> 15 | C8: =SUMIFS('Sold Items'!$H$2:$H$720,'Sold Items'!$R$2:$R$720,">="&A8,'Sold Items'!$R$2:$R$720,"<"&EDATE(A8,1)) -> 2406700 | D8: =COUNTIFS('Historical Sales'!$A$2:$A$243,">="&A8,'Historical Sales'!$A$2:$A$243,"<"&EDATE(A8,1)) -> 5 | E8: =SUMIFS('Historical Sales'!$F$2:$F$243,'Historical Sales'!$A$2:$A$243,">="&A8,'Historical Sales'!$A$2:$A$243,"<"&EDATE(A8,1)) -> 178900 | F8: =C8+E8 -> 2585600
A9: 45413 | B9: =COUNTIFS('Sold Items'!$R$2:$R$720,">="&A9,'Sold Items'!$R$2:$R$720,"<"&EDATE(A9,1)) -> 12 | C9: =SUMIFS('Sold Items'!$H$2:$H$720,'Sold Items'!$R$2:$R$720,">="&A9,'Sold Items'!$R$2:$R$720,"<"&EDATE(A9,1)) -> 2079000 | D9: =COUNTIFS('Historical Sales'!$A$2:$A$243,">="&A9,'Historical Sales'!$A$2:$A$243,"<"&EDATE(A9,1)) -> 10 | E9: =SUMIFS('Historical Sales'!$F$2:$F$243,'Historical Sales'!$A$2:$A$243,">="&A9,'Historical Sales'!$A$2:$A$243,"<"&EDATE(A9,1)) -> 321000 | F9: =C9+E9 -> 2400000
A10: 45444 | B10: =COUNTIFS('Sold Items'!$R$2:$R$720,">="&A10,'Sold Items'!$R$2:$R$720,"<"&EDATE(A10,1)) -> 15 | C10: =SUMIFS('Sold Items'!$H$2:$H$720,'Sold Items'!$R$2:$R$720,">="&A10,'Sold Items'!$R$2:$R$720,"<"&EDATE(A10,1)) -> 2690300 | D10: =COUNTIFS('Historical Sales'!$A$2:$A$243,">="&A10,'Historical Sales'!$A$2:$A$243,"<"&EDATE(A10,1)) -> 5 | E10: =SUMIFS('Historical Sales'!$F$2:$F$243,'Historical Sales'!$A$2:$A$243,">="&A10,'Historical Sales'!$A$2:$A$243,"<"&EDATE(A10,1)) -> 144700 | F10: =C10+E10 -> 2835000
A11: 45474 | B11: =COUNTIFS('Sold Items'!$R$2:$R$720,">="&A11,'Sold Items'!$R$2:$R$720,"<"&EDATE(A11,1)) -> 12 | C11: =SUMIFS('Sold Items'!$H$2:$H$720,'Sold Items'!$R$2:$R$720,">="&A11,'Sold Items'!$R$2:$R$720,"<"&EDATE(A11,1)) -> 2308200 | D11: =COUNTIFS('Historical Sales'!$A$2:$A$243,">="&A11,'Historical Sales'!$A$2:$A$243,"<"&EDATE(A11,1)) -> 9 | E11: =SUMIFS('Historical Sales'!$F$2:$F$243,'Historical Sales'!$A$2:$A$243,">="&A11,'Historical Sales'!$A$2:$A$243,"<"&EDATE(A11,1)) -> 313700 | F11: =C11+E11 -> 2621900
A12: 45505 | B12: =COUNTIFS('Sold Items'!$R$2:$R$720,">="&A12,'Sold Items'!$R$2:$R$720,"<"&EDATE(A12,1)) -> 12 | C12: =SUMIFS('Sold Items'!$H$2:$H$720,'Sold Items'!$R$2:$R$720,">="&A12,'Sold Items'!$R$2:$R$720,"<"&EDATE(A12,1)) -> 1528500 | D12: =COUNTIFS('Historical Sales'!$A$2:$A$243,">="&A12,'Historical Sales'!$A$2:$A$243,"<"&EDATE(A12,1)) -> 5 | E12: =SUMIFS('Historical Sales'!$F$2:$F$243,'Historical Sales'!$A$2:$A$243,">="&A12,'Historical Sales'!$A$2:$A$243,"<"&EDATE(A12,1)) -> 185800 | F12: =C12+E12 -> 1714300
A13: 45536 | B13: =COUNTIFS('Sold Items'!$R$2:$R$720,">="&A13,'Sold Items'!$R$2:$R$720,"<"&EDATE(A13,1)) -> 20 | C13: =SUMIFS('Sold Items'!$H$2:$H$720,'Sold Items'!$R$2:$R$720,">="&A13,'Sold Items'!$R$2:$R$720,"<"&EDATE(A13,1)) -> 2589200 | D13: =COUNTIFS('Historical Sales'!$A$2:$A$243,">="&A13,'Historical Sales'!$A$2:$A$243,"<"&EDATE(A13,1)) -> 4 | E13: =SUMIFS('Historical Sales'!$F$2:$F$243,'Historical Sales'!$A$2:$A$243,">="&A13,'Historical Sales'!$A$2:$A$243,"<"&EDATE(A13,1)) -> 167800 | F13: =C13+E13 -> 2757000
... A38: 46296 | B38: =COUNTIFS('Sold Items'!$R$2:$R$720,">="&A38,'Sold Items'!$R$2:$R$720,"<"&EDATE(A38,1)) -> 9 | C38: =SUMIFS('Sold Items'!$H$2:$H$720,'Sold Items'!$R$2:$R$720,">="&A38,'Sold Items'!$R$2:$R$720,"<"&EDATE(A38,1)) -> 1837500 | D38: =COUNTIFS('Historical Sales'!$A$2:$A$243,">="&A38,'Historical Sales'!$A$2:$A$243,"<"&EDATE(A38,1)) -> 3 | E38: =SUMIFS('Historical Sales'!$F$2:$F$243,'Historical Sales'!$A$2:$A$243,">="&A38,'Historical Sales'!$A$2:$A$243,"<"&EDATE(A38,1)) -> 116100 | F38: =C38+E38 -> 1953600
A39: Total | B39: =SUM(B2:B38) -> 719 | C39: =SUM(C2:C38) -> 126164900 | D39: =SUM(D2:D38) -> 242 | E39: =SUM(E2:E38) -> 8707300 | F39: =SUM(F2:F38) -> 134872200
A41: Full-record revenue counts sales by Sold At date. Layaways still being paid are excluded (not verified yet). October 2026 is month-to-date (up to Oct 13).

Sheet Sold Items
A1: Barcode | B1: Brand | C1: Model | D1: Category | E1: Colour / Material | F1: Hardware | G1: Date Code | H1: Price | I1: Markup | J1: Consignor Payout | K1: Consignor | L1: Condition | M1: Accessories | N1: Inquiry Channel | O1: Fulfillment | P1: Intake At | Q1: Listed At | R1: Sold At | S1: Buyer | T1: Sale Type | U1: Layaway Months | V1: Payment Verified At | W1: Payout Released At
A2: 25053755 | B2: Tom Ford | C2: Oversized Round Sunglasses | D2: Accessory | H2: 8400 | I2: 3000 | J2: 5400 | K2: Carlo Go | L2: Pristine, no visible signs of use | M2: Dust bag, Receipt | N2: tiktok | O2: courier | P2: 45170.485 | Q2: 45181.535 | R2: 45200.622 | S2: Zara Lopez | T2: full_payment | V2: 45201.476 | W2: 45216.498
A3: 75084859 | B3: Hermes | C3: Picotin Lock 18 | D3: Tote | E3: Nata Clemence Leather | F3: Palladium | G3: Stamp B (2023) | H3: 270800 | I3: 32496 | J3: 238304 | K3: Pia Andrada | L3: Excellent, very light wear on corners | M3: Dust bag, Box, Clochette, Lock and Keys | N3: instagram | O3: drop_off | P3: 45161.503 | Q3: 45181.74 | R3: 45201.653 | S3: Marco Cruz | T3: layaway | U3: 2 | V3: 45262.454 | W3: 45274.73
A4: 00096059 | B4: Louis Vuitton | C4: Coussin BB | D4: Handbag | E4: Monogram Beads Noir | H4: 187300 | I4: 18000 | J4: 169300 | K4: Angelica Co | L4: Excellent, very light wear on corners. Microchip present | M4: Dust bag | N4: facebook | O4: walk_in | P4: 45143.562 | Q4: 45161.656 | R4: 45201.759 | S4: Gabrielle Del Rosario | T4: full_payment | V4: 45203.447 | W4: 45210.417
A5: 66584123 | B5: Loewe | C5: Flamenco Tote Bag Large | D5: Tote | E5: Black Nappa Calfskin Leather | H5: 175600 | I5: 18000 | J5: 157600 | K5: Gerald Gatchalian | L5: Excellent, very light wear on corners | M5: Dust bag | N5: instagram | O5: walk_in | P5: 45179.66 | Q5: 45190.625 | R5: 45204.585 | S5: Ramon Torres | T5: full_payment | V5: 45204.627 | W5: 45222.758
A6: 26933051 | B6: Chanel | C6: Le Boy Old Medium | D6: Shoulder Bag | E6: Red Chevron Caviar Leather | F6: Aged Gold | G6: Series 25 | H6: 266600 | I6: 31992 | J6: 234608 | K6: Marco Aguilar | L6: Brand new, never used, complete with tags | M6: Dust bag | N6: instagram | O6: drop_off | P6: 45171.737 | Q6: 45194.486 | R6: 45211.57 | S6: Tina Gatchalian | T6: full_payment | V6: 45212.609 | W6: 45230.664
A7: 15938107 | B7: Louis Vuitton | C7: Capucines Handbag | D7: Handbag | E7: Metallic Gold Goatskin Leather & Mink Fur | H7: 571000 | I7: 68520 | J7: 502480 | K7: Bianca Soriano | L7: Good, visible wear on corners and handles. Microchip present | M7: Dust bag | N7: instagram | O7: drop_off | P7: 45153.722 | Q7: 45162.554 | R7: 45212.806 | S7: Frances Aquino | T7: full_payment | V7: 45212.848 | W7: 45230.551
A8: 33831483 | B8: Chanel | C8: Classic Flap Card Holder | D8: Small Leather Goods | E8: Caramel Quilted Caviar Leather | F8: Light Gold | H8: 52300 | I8: 13000 | J8: 39300 | K8: Bianca Zamora | L8: Pristine, no visible signs of use. Microchip present | M8: Dust bag | N8: instagram | O8: drop_off | P8: 45082.761 | Q8: 45106.585 | R8: 45213.499 | S8: Carla Ramos | T8: full_payment | V8: 45215.791 | W8: 45226.493
A9: 03707963 | B9: Polene | C9: Numéro Neuf East West Ebony Graine Leather | D9: Handbag | H9: 59100 | I9: 13000 | J9: 46100 | K9: Teresa Madrigal | L9: Excellent, very light wear on corners | M9: Dust bag | N9: instagram | O9: drop_off | P9: 45171.66 | Q9: 45194.624 | R9: 45216.49 | S9: Bianca Pascual | T9: full_payment | V9: 45218.459 | W9: 45236.462
A10: 43941435 | B10: Balenciaga | C10: Ville Top Handle Bag | D10: Handbag | E10: Brown Grained Calfskin Leather | F10: Gold | H10: 65900 | I10: 13000 | J10: 52900 | K10: Andrea Uy | L10: Very good, light scratches on hardware | M10: Dust bag, Box | N10: instagram | O10: drop_off | P10: 45177.715 | Q10: 45196.567 | R10: 45220.476 | S10: Michelle Chua | T10: full_payment | V10: 45221.569 | W10: 45231.544
A11: 38471483 | B11: Chanel | C11: 19 Flap Cardholder | D11: Small Leather Goods | E11: Peach Lambskin Leather | F11: Palladium | H11: 50200 | I11: 13000 | J11: 37200 | K11: Rosario Ocampo | L11: Excellent, very light wear on corners. Microchip present | M11: Dust bag, Box, Receipt | N11: walk_in | O11: drop_off | P11: 45169.557 | Q11: 45179.484 | R11: 45220.819 | S11: Gabriel Flores | T11: full_payment | V11: 45222.492 | W11: 45230.72
A12: 63035195 | B12: Bally | C12: Tirk Mens Coffee Travel Long Wallet | D12: Wallet | H12: 25100 | I12: 10000 | J12: 15100 | K12: Yasmin Ilagan | L12: Good, visible wear on corners and handles | M12: Dust bag, Receipt | N12: messenger | O12: drop_off | P12: 45186.455 | Q12: 45200.687 | R12: 45227.662 | S12: Christian Mendoza | T12: full_payment | V12: 45228.78 | W12: 45234.432
A13: 41567547 | B13: Louis Vuitton | C13: Speedy 30 | D13: Handbag | E13: Damier Ebene Canvas | F13: Gold | H13: 76300 | I13: 13000 | J13: 63300 | K13: Carlo Madrigal | L13: Very good, light scratches on hardware. Microchip present | M13: Dust bag, Receipt | N13: walk_in | O13: drop_off | P13: 45177.59 | Q13: 45196.505 | R13: 45230.772 | S13: Eduardo Zamora | T13: full_payment | V13: 45232.439 | W13: 45246.77
A14: 31702587 | B14: Louis Vuitton | C14: Montaigne BB | D14: Handbag | E14: Taupe Monogram Empreinte Leather | G14: SP1197 | H14: 133800 | I14: 18000 | J14: 115800 | K14: Kim De Leon | L14: Very good, light scratches on hardware | M14: Dust bag, Box | N14: messenger | O14: drop_off | P14: 45194.605 | Q14: 45216.621 | R14: 45233.69 | S14: Pauline Lacson | T14: full_payment | V14: 45233.731 | W14: 45250.717
A15: 34498875 | B15: Bottega Veneta | C15: Red Multicolor Karung Flap Long Wallet | D15: Wallet | H15: 18900 | I15: 6000 | J15: 12900 | K15: Carla Santos | L15: Excellent, very light wear on corners | M15: Dust bag | N15: whatsapp | O15: drop_off | P15: 45162.78 | Q15: 45173.733 | R15: 45234.577 | S15: Frances Lacson | T15: full_payment | V15: 45235.542 | W15: 45248.651
A16: 07074875 | B16: Chanel | C16: Boy Small Chevron | D16: Shoulder Bag | E16: Black Caviar Leather | F16: Aged Gold | G16: Series 24 | H16: 289000 | I16: 34680 | J16: 254320 | K16: Adrian Castillo | L16: Pristine, no visible signs of use | M16: Dust bag, Box | N16: messenger | O16: walk_in | P16: 45082.652 | Q16: 45102.721 | R16: 45235.532 | S16: Danica Ramos | T16: full_payment | V16: 45235.717 | W16: 45248.6
A17: 50862139 | B17: Christian Dior | C17: Lady Dior Medium | D17: Handbag | E17: Dark Red Cannage Quilted Lambskin Leather | F17: Light Gold | H17: 266600 | I17: 31992 | J17: 234608 | K17: Marco Aguilar | L17: Good, visible wear on corners and handles | M17: Dust bag | N17: facebook | O17: courier | P17: 45196.488 | Q17: 45213.509 | R17: 45237.775 | S17: Bea Torres | T17: full_payment | V17: 45237.817 | W17: 45248.513
A18: 26186555 | B18: Gucci | C18: Mini Torchon Top Handle Shoulder Bag | D18: Shoulder Bag | E18: Black GG Marmont Matelasse Calfskin Leather | H18: 81600 | I18: 13000 | J18: 68600 | K18: Miguel Santos | L18: Pristine, no visible signs of use | M18: Dust bag | N18: email | O18: courier | P18: 45119.492 | Q18: 45129.719 | R18: 45243.463 | S18: Erika De Leon | T18: full_payment | V18: 45245.778 | W18: 45256.595
A19: 10087227 | B19: Gucci | C19: Horsebit 1955 Soft Small East West Shoulder Bag Supreme Canvas | D19: Shoulder Bag | H19: 128600 | I19: 18000 | J19: 110600 | K19: Kim Santos | L19: Excellent, very light wear on corners | M19: Dust bag, Box | N19: website | O19: pickup | P19: 45188.449 | Q19: 45212.756 | R19: 45243.535 | S19: Maria Velasco | T19: full_payment | V19: 45243.681 | W19: 45252.748
A20: 40964667 | B20: Chanel | C20: Boy Flap Compact Wallet | D20: Wallet | E20: Purple Caviar Leather | F20: Light Gold | G20: Series 29 | H20: 49000 | I20: 10000 | J20: 39000 | K20: Rafael Valdez | L20: Excellent, very light wear on corners | M20: Dust bag, Box, Authenticity card | N20: instagram | O20: walk_in | P20: 45213.606 | Q20: 45229.619 | R20: 45244.688 | S20: Eduardo Ocampo | T20: full_payment | V20: 45244.73 | W20: 45258.482
A21: 34665019 | B21: Hermes | C21: Kelly Wallet | D21: Wallet | E21: Epsom Leather | F21: Palladium | H21: 221800 | I21: 26616 | J21: 195184 | K21: Miguel Santos | L21: Very good, light scratches on hardware | M21: Dust bag, Box, Clochette, Lock and Keys | N21: instagram | O21: courier | P21: 45222.64 | Q21: 45235.676 | R21: 45244.723 | S21: Michelle Navarro | T21: full_payment | V21: 45244.765 | W21: 45258.708
A22: 38685243 | B22: Hermes | C22: Bride-a-Brac Vanity Case | D22: Crossbody | E22: Orange Toile Canvas | F22: Palladium | H22: 59400 | I22: 13000 | J22: 46400 | K22: Katrina Lim | L22: Very good, light scratches on hardware | M22: Dust bag, Box, Receipt, Felt | N22: email | O22: drop_off | P22: 45187.483 | Q22: 45207.619 | R22: 45245.795 | S22: Rica Cojuangco | T22: full_payment | V22: 45246.681 | W22: 45261.433
A23: 42022459 | B23: Chanel | C23: Coco Handle Medium | D23: Handbag | E23: Red Quilted Caviar Leather Aged | F23: Aged Gold | G23: Series 27 | H23: 244200 | I23: 29304 | J23: 214896 | K23: Mika Reyes | L23: Excellent, very light wear on corners | M23: Dust bag, Box, Authenticity card | N23: instagram | O23: walk_in | P23: 45202.762 | Q23: 45214.674 | R23: 45250.635 | S23: Nina Roxas | T23: full_payment | V23: 45252.424 | W23: 45261.61
A24: 65969211 | B24: Saint Laurent | C24: College Bag Medium | D24: Handbag | E24: Burgundy Monogram Chevron Sheepskin Leather | F24: Ruthenium | H24: 83400 | I24: 13000 | J24: 70400 | K24: Hannah Roxas | L24: Good, visible wear on corners and handles | M24: Dust bag, Box | N24: facebook | O24: drop_off | P24: 45219.754 | Q24: 45228.513 | R24: 45252.758 | S24: Nicole Laurel | T24: full_payment | V24: 45254.658 | W24: 45264.544
A25: 77972283 | B25: Hermes | C25: Picotin Lock 22 | D25: Tote | E25: Rouge Casaque Clemence Leather | F25: Palladium | G25: Stamp X (2016) | H25: 187300 | I25: 18000 | J25: 169300 | K25: Jasmine Laurel | L25: Good, visible wear on corners and handles | M25: Dust bag, Box, Rain cover | N25: instagram | O25: pickup | P25: 45198.474 | Q25: 45211.719 | R25: 45256.725 | S25: Benjamin Madrigal | T25: full_payment | V25: 45257.683 | W25: 45275.581
A26: 28883003 | B26: Gucci | C26: Guccissima Black Signature Calfskin Leather Bifold Wallet | D26: Wallet | H26: 42800 | I26: 10000 | J26: 32800 | K26: Miguel Santos | L26: Pristine, no visible signs of use | M26: Dust bag, Box | N26: walk_in | O26: walk_in | P26: 45199.486 | Q26: 45215.658 | R26: 45257.722 | S26: Vincent Del Rosario | T26: full_payment | V26: 45259.605 | W26: 45273.636
A27: 07974459 | B27: Gucci | C27: Dionysus Mini GG Supreme Coated Canvas | D27: Shoulder Bag | H27: 65900 | I27: 13000 | J27: 52900 | K27: Paolo Laurel | L27: Brand new, never used, complete with tags | M27: Dust bag, Box | N27: walk_in | O27: walk_in | P27: 45239.644 | Q27: 45251.458 | R27: 45260.459 | S27: Danica Roxas | T27: full_payment | V27: 45262.533 | W27: 45271.533
A28: 16644411 | B28: Chanel | C28: Mini Coco Handle | D28: Handbag | E28: Black Quilted Caviar Leather | F28: Light Gold | H28: 317000 | I28: 38040 | J28: 278960 | K28: Hannah Yap | L28: Brand new, never used, complete with tags. Microchip present | M28: Dust bag, Box, Authenticity card | N28: instagram | O28: courier | P28: 45212.482 | Q28: 45227.456 | R28: 45260.542 | S28: Olivia Soriano | T28: full_payment | V28: 45261.68 | W28: 45270.714
A29: 56374075 | B29: Chanel | C29: Wallet On Chain | D29: Crossbody | E29: Iridescent Lambskin Leather | H29: 175600 | I29: 18000 | J29: 157600 | K29: Paolo Laurel | L29: Excellent, very light wear on corners. Microchip present | M29: Dust bag, Box | N29: instagram | O29: courier | P29: 45185.535 | Q29: 45203.565 | R29: 45261.49 | S29: Carla Rivera | T29: full_payment | V29: 45261.562 | W29: 45272.733
A30: 68136251 | B30: Chanel | C30: Flap Card Holder | D30: Small Leather Goods | E30: Gray Lambskin Leather | F30: Light Gold | G30: Series 31 | H30: 50200 | I30: 13000 | J30: 37200 | K30: Zara Domingo | L30: Pristine, no visible signs of use | M30: Dust bag, Receipt | N30: instagram | O30: courier | P30: 45216.662 | Q30: 45229.774 | R30: 45261.66 | S30: Jericho Castro | T30: full_payment | V30: 45263.753 | W30: 45270.42
A31: 12096315 | B31: Givenchy | C31: White Rubber Pool Slides | D31: Shoes | H31: 24000 | I31: 10000 | J31: 14000 | K31: Antonio Aquino | L31: Good, visible wear on corners and handles. Size 42 EU | M31: Dust bag, Box | N31: website | O31: walk_in | P31: 45203.524 | Q31: 45227.757 | R31: 45261.817 | S31: Patricia Javier | T31: full_payment | V31: 45262.446 | W31: 45269.519
A32: 90086203 | B32: Louis Vuitton | C32: Neo Noe BB | D32: Handbag | E32: Navy Blue Epi Leather | F32: Silver | H32: 86800 | I32: 13000 | J32: 73800 | K32: Miguel Santos | L32: Excellent, very light wear on corners. Microchip present | M32: Dust bag, Box | N32: messenger | O32: walk_in | P32: 45215.72 | Q32: 45235.613 | R32: 45262.616 | S32: Mika Sy | T32: full_payment | V32: 45264.771 | W32: 45273.765
A33: 92724283 | B33: Chanel | C33: Paris Limited Edition Double Flap Bag Medium | D33: Shoulder Bag | E33: Black Lambskin Leather | F33: Mix | G33: Series 3 | H33: 210600 | I33: 25272 | J33: 185328 | K33: Miguel Santos | L33: Pristine, no visible signs of use | M33: Dust bag, Box | N33: website | O33: walk_in | P33: 45111.552 | Q33: 45131.646 | R33: 45262.669 | S33: Teresa Ayala | T33: full_payment | V33: 45264.575 | W33: 45271.678
A34: 27633979 | B34: Louis Vuitton | C34: Neo Noe MM Bi-Color Monogram Empreinte Leather | D34: Handbag | H34: 112900 | I34: 18000 | J34: 94900 | K34: Ramon Javier | L34: Excellent, very light wear on corners. Microchip present | M34: Dust bag, Box | N34: instagram | O34: drop_off | P34: 45188.446 | Q34: 45212.492 | R34: 45266.46 | S34: Veronica Aguilar | T34: full_payment | V34: 45266.66 | W34: 45274.43
A35: 61516091 | B35: Loewe | C35: Mini Gate Ash Blue | D35: Crossbody | E35: Smooth Calfskin Leather Crossbody Bag | H35: 86800 | I35: 13000 | J35: 73800 | K35: Kim Tuason | L35: Excellent, very light wear on corners | M35: Dust bag, Box | N35: instagram | O35: drop_off | P35: 45234.417 | Q35: 45252.577 | R35: 45266.692 | S35: Patricia Tuason | T35: full_payment | V35: 45268.56 | W35: 45275.479
A36: 33980731 | B36: Louis Vuitton | C36: OntheGo MM | D36: Tote | E36: Black Monogram Empreinte Leather | F36: Gold | H36: 107700 | I36: 18000 | J36: 89700 | K36: Ana Gonzales | L36: Very good, light scratches on hardware. Microchip present | M36: Dust bag, Box | N36: whatsapp | O36: drop_off | P36: 45232.469 | Q36: 45248.634 | R36: 45266.812 | S36: Jasmine Castillo | T36: full_payment | V36: 45268.531 | W36: 45275.484
A37: 82160955 | B37: Bottega Veneta | C37: Mount Envelope Small Green | D37: Handbag | E37: Grained Calfskin Leather Bag | H37: 112900 | I37: 18000 | J37: 94900 | K37: Vincent Andrada | L37: Pristine, no visible signs of use | M37: Dust bag, Receipt | N37: walk_in | O37: drop_off | P37: 45199.781 | Q37: 45218.52 | R37: 45267.467 | S37: Rafael Uy | T37: full_payment | V37: 45268.74 | W37: 45281.528
A38: 81669435 | B38: Hermes | C38: Pencilver Charm with Notebook | D38: Accessory | H38: 86800 | I38: 13000 | J38: 73800 | K38: Mika Soriano | L38: Very good, light scratches on hardware | M38: Dust bag, Box, Felt | N38: tiktok | O38: courier | P38: 45250.701 | Q38: 45263.755 | R38: 45267.503 | S38: Hannah Laurel | T38: full_payment | V38: 45268.521 | W38: 45284.686
A39: 15685691 | B39: Gucci | C39: GG Bi-Fold Wallet | D39: Wallet | E39: Beige & Ebony Supreme Monogram Canvas | H39: 37600 | I39: 10000 | J39: 27600 | K39: Lara Aquino | L39: Very good, light scratches on hardware | M39: Dust bag, Box, Receipt | N39: instagram | O39: pickup | P39: 45151.434 | Q39: 45164.768 | R39: 45267.785 | S39: Regina Ocampo | T39: full_payment | V39: 45269.756 | W39: 45275.483
A40: 12261435 | B40: Louis Vuitton | C40: Ostrich Leather Zippy Card Holder | D40: Wallet | H40: 22000 | I40: 10000 | J40: 12000 | K40: Ramon Tan | L40: Excellent, very light wear on corners | M40: Dust bag, Box, Receipt | N40: walk_in | O40: courier | P40: 45219.576 | Q40: 45233.48 | R40: 45270.537 | S40: Antonio Sy | T40: full_payment | V40: 45271.427 | W40: 45289.769
...

Sheet Current Stock
A1: Barcode | B1: Brand | C1: Model | D1: Category | E1: Colour / Material | F1: Price | G1: Markup | H1: Consignor Payout | I1: Status | J1: Consignor | K1: Condition | L1: Intake At | M1: Listed At | N1: Layaway Buyer | O1: Layaway Months | P1: Layaway Total Due | Q1: Paid So Far
A2: 19010363 | B2: Hermes | C2: Zipengo Gold PM | D2: Wallet | E2: Evercolor Leather | F2: 109700 | G2: 18000 | H2: 91700 | I2: Available | J2: Angelica Andrada | K2: Pristine, no visible signs of use | L2: 46192.683 | M2: 46214.608
A3: 40011579 | B3: Celine | C3: Classic Box | D3: Shoulder Bag | E3: Brown Smooth Calfskin Leather Shoulder Bag | F3: 86800 | G3: 13000 | H3: 73800 | I3: Available | J3: Yasmin Garcia | K3: Pristine, no visible signs of use | L3: 46190.68 | M3: 46214.629
A4: 52246587 | B4: Chanel | C4: Classic Double Flap Maxi Metallic | D4: Shoulder Bag | E4: Caviar Leather | F4: 322600 | G4: 38712 | H4: 283888 | I4: Available | J4: Patricia Pascual | K4: Very good, light scratches on hardware | L4: 46192.469 | M4: 46214.676
A5: 00863803 | B5: Fendi | C5: First Small Nappa | D5: Handbag | E5: Shiny Torto Dark Beige Smooth Calfskin Leather | F5: 144300 | G5: 18000 | H5: 126300 | I5: Available | J5: Ramon Javier | K5: Excellent, very light wear on corners | L5: 46211.633 | M5: 46222.547
A6: 99430203 | B6: Chanel | C6: Classic Double Flap | D6: Shoulder Bag | E6: Black Chevron Caviar Leather | F6: 457000 | G6: 54840 | H6: 402160 | I6: Available | J6: Eduardo Co | K6: Very good, light scratches on hardware | L6: 46201.696 | M6: 46222.555
A7: 75461691 | B7: Louis Vuitton | C7: Alma BB | D7: Handbag | E7: Damier Ebene Canvas | F7: 101200 | G7: 18000 | H7: 83200 | I7: Available | J7: Iris Navarro | K7: Pristine, no visible signs of use. Microchip present | L7: 46218.736 | M7: 46229.533
A8: 30156347 | B8: Chanel | C8: 19 Small | D8: Handbag | E8: Light Pink Quilted Lambskin Leather | F8: 305800 | G8: 36696 | H8: 269104 | I8: Available | J8: Paolo Laurel | K8: Very good, light scratches on hardware | L8: 46210.766 | M8: 46233.526
A9: 20485947 | B9: Hermes | C9: Picotin Micro Lucky Daisy | D9: Tote | E9: Nata Swift Leather | F9: 175600 | G9: 18000 | H9: 157600 | I9: Reserved (layaway) | J9: Marco Aguilar | K9: Good, visible wear on corners and handles | L9: 46224.724 | M9: 46239.573 | N9: Danica Mendoza | O9: 3 | P9: 180868 | Q9: 45217
A10: 06437947 | B10: Chanel | C10: Boy Galuchat Mini Flap Bag | D10: Shoulder Bag | E10: White Quilted Lambskin Leather | F10: 233000 | G10: 27960 | H10: 205040 | I10: Available | J10: Veronica Domingo | K10: Brand new, never used, complete with tags | L10: 46227.475 | M10: 46240.488
A11: 35363899 | B11: Hermes | C11: Evelyne 16 TPM | D11: Handbag | E11: Gold Epsom Leather | F11: 291000 | G11: 34920 | H11: 256080 | I11: Reserved (layaway) | J11: Pauline Valdez | K11: Good, visible wear on corners and handles | L11: 46231.618 | M11: 46241.67 | N11: Michelle Zamora | O11: 2 | P11: 296820 | Q11: 98940
A12: 12063547 | B12: Givenchy | C12: White Rubber Pool Slides 41 EU | D12: Shoes | F12: 24000 | G12: 10000 | H12: 14000 | I12: Available | J12: Teresa Gatchalian | K12: Good, visible wear on corners and handles | L12: 46234.72 | M12: 46243.701
A13: 91346235 | B13: Hermes | C13: Mini Jypsiere | D13: Handbag | E13: Gris Meyer Evercolor Leather | F13: 703400 | G13: 84408 | H13: 618992 | I13: Available | J13: Rica Mercado | K13: Good, visible wear on corners and handles | L13: 46221.751 | M13: 46244.518
A14: 17371963 | B14: Goyard | C14: Saint Louis PM Gray | D14: Handbag | E14: Goyardine Canvas | F14: 137900 | G14: 18000 | H14: 119900 | I14: Available | J14: Jericho Castro | K14: Brand new, never used, complete with tags | L14: 46224.59 | M14: 46248.537
A15: 67164987 | B15: Chanel | C15: 19 Wallet On Chain | D15: Crossbody | F15: 246300 | G15: 29556 | H15: 216744 | I15: Available | J15: Christian Aquino | K15: Pristine, no visible signs of use. Microchip present | L15: 46240.542 | M15: 46251.488
A16: 74464827 | B16: Louis Vuitton | C16: City Keepall Shoulder Bag | D16: Shoulder Bag | E16: Monogram Eclipse Canvas | F16: 109600 | G16: 18000 | H16: 91600 | I16: Available | J16: Camille Lopez | K16: Good, visible wear on corners and handles. Microchip present | L16: 46236.548 | M16: 46251.557
A17: 68030523 | B17: Stuart Weitzman | C17: Leather White Sneakers 36.5 EU(23.3 cm) | D17: Shoes | F17: 13600 | G17: 6000 | H17: 7600 | I17: Available | J17: Paolo Domingo | K17: Very good, light scratches on hardware | L17: 46242.763 | M17: 46252.68
A18: 20453179 | B18: Hermes | C18: Picotin Micro | D18: Tote | E18: Black Ostrich Leather | F18: 658600 | G18: 79032 | H18: 579568 | I18: Available | J18: Lara Valdez | K18: Excellent, very light wear on corners | L18: 46233.569 | M18: 46254.423
A19: PMS-CONS-2026-00074 | B19: Gucci | C19: Super Mini Dionysus GG Supreme Canvas | D19: Shoulder Bag | F19: 57500 | G19: 13000 | H19: 44500 | I19: Available | J19: Miguel Santos | K19: Pristine, no visible signs of use | L19: 46244.547 | M19: 46255.466
A20: 62794555 | B20: Hermes | C20: Evelyne TPM | D20: Handbag | E20: Etoupe Taurillon Clemence Leather | F20: 204900 | G20: 24588 | H20: 180312 | I20: Available | J20: Jessa Panlilio | K20: Excellent, very light wear on corners | L20: 46241.64 | M20: 46256.6
A21: 58811963 | B21: Christian Dior | C21: Essenstial Tote Bag Small | D21: Tote | E21: Black Archicannage Quilted Calfskin Leather | F21: 151400 | G21: 18000 | H21: 133400 | I21: Available | J21: Carla Pascual | K21: Pristine, no visible signs of use | L21: 46240.589 | M21: 46257.574
A22: 03068731 | B22: Christian Dior | C22: Walk'n'Dior Sneakers | D22: Shoes | E22: Beige Oblique Embroidered Cotton Motif | F22: 52300 | G22: 13000 | H22: 39300 | I22: Available | J22: Bianca Mercado | K22: Very good, light scratches on hardware. Size 37 Eu | L22: 46235.741 | M22: 46257.614
A23: 50845755 | B23: Chanel | C23: Trendy Wallet on Chain(WOC) Black Lambskin Leather | D23: Crossbody | E23: Light | F23: 187300 | G23: 18000 | H23: 169300 | I23: Available | J23: Pauline Valdez | K23: Excellent, very light wear on corners | L23: 46241.475 | M23: 46258.472
A24: 82230843 | B24: Prada | C24: Re-Nylon Demi Lune Bandoliera Crossbody Bag | D24: Crossbody | F24: 87700 | G24: 13000 | H24: 74700 | I24: Available | J24: Erika Rivera | K24: Very good, light scratches on hardware | L24: 46243.705 | M24: 46259.64
A25: 00593979 | B25: Chanel | C25: Gabrielle Clutch with Chain | D25: Clutch | E25: Black Quilted Aged Calfskin Leather | F25: 140900 | G25: 18000 | H25: 122900 | I25: Available | J25: Hannah Roxas | K25: Very good, light scratches on hardware | L25: 46245.726 | M25: 46260.656
A26: 91525435 | B26: Chanel | C26: Classic Coin Case Flap Compact Wallet | D26: Wallet | E26: Iredescent Beige Quilted Caviar Leather | F26: 50200 | G26: 13000 | H26: 37200 | I26: Available | J26: Lara Aquino | K26: Pristine, no visible signs of use | L26: 46242.456 | M26: 46262.5
A27: 16426299 | B27: Hermes | C27: Picotin Lock 18 | D27: Tote | E27: Gold Clemence Leather | F27: 255400 | G27: 30648 | H27: 224752 | I27: Available | J27: Ana Tan | K27: Excellent, very light wear on corners | L27: 46253.688 | M27: 46262.574
A28: 30468411 | B28: Alexander McQueen | C28: New Court Lace Up Shoes | D28: Handbag | E28: White for Women | F28: 18900 | G28: 6000 | H28: 12900 | I28: Available | J28: Bianca Domingo | K28: Excellent, very light wear on corners. Size 39 EU | L28: 46252.505 | M28: 46263.625
A29: 483878991 | B29: Roger Vivier | C29: Trompette Ballerinas | D29: Shoes | E29: Black Shoes Patent Leather | F29: 73100 | G29: 13000 | H29: 60100 | I29: Available | J29: Kim De Leon | K29: Excellent, very light wear on corners. Size 39.5 EU | L29: 46254.619 | M29: 46263.686
A30: 72109371 | B30: Hermes | C30: Heritage Buckle Reversible Belt | D30: Belt | E30: White Epsome Leather | F30: 52300 | G30: 13000 | H30: 39300 | I30: Available | J30: Andrea Laurel | K30: Good, visible wear on corners and handles. Size 85 | L30: 46251.506 | M30: 46265.668
A31: 42370363 | B31: Hermes | C31: Evelyne 16 TPM | D31: Handbag | E31: Etoupe Clemence Leather with Navy Blue Strap | F31: 208400 | G31: 25008 | H31: 183392 | I31: Reserved (layaway) | J31: Pauline Lim | K31: Excellent, very light wear on corners | L31: 46242.747 | M31: 46266.588 | N31: Miguel De Leon | O31: 3 | P31: 214652 | Q31: 53663
A32: 02937659 | B32: Hermes | C32: In The Loop 18 | D32: Handbag | E32: Black/Noir Clemence Leather | F32: 255400 | G32: 30648 | H32: 224752 | I32: Available | J32: Paolo Laurel | K32: Brand new, never used, complete with tags | L32: 46257.659 | M32: 46267.471
A33: 83672379 | B33: Hermes | C33: Kelly 25 Sellier | D33: Handbag | E33: Vert Yucca Epsom Leather | F33: 1355000 | G33: 162600 | H33: 1192400 | I33: Available | J33: Ramon Velasco | K33: Good, visible wear on corners and handles | L33: 46255.604 | M33: 46268.479
A34: 62541883 | B34: Hermes | C34: Evelyne 16 TPM | D34: Handbag | E34: Etoupe Leather Clemence with Navy Blue Strap | F34: 214900 | G34: 25788 | H34: 189112 | I34: Available | J34: Kim Del Rosario | K34: Pristine, no visible signs of use | L34: 46248.442 | M34: 46268.481
A35: 00036923 | B35: Hermes | C35: Mini Herbag Zip 20 | D35: Tote | E35: Ebene Canvas | F35: 285500 | G35: 34260 | H35: 251240 | I35: Available | J35: Pauline Co | K35: Pristine, no visible signs of use | L35: 46249.517 | M35: 46269.481
A36: 86784571 | B36: Christian Dior | C36: My Dior Mini Top Handle Chain Strap Bag | D36: Handbag | E36: Black Cannage Lambskin Leather Light | F36: 151400 | G36: 18000 | H36: 133400 | I36: Available | J36: Kim Santos | K36: Excellent, very light wear on corners | L36: 46253.694 | M36: 46269.66
A37: 78243899 | B37: Hermes | C37: Evelyne III GM Jaune Poussin Clemence | D37: Handbag | E37: Palladium Hardware | F37: 175600 | G37: 18000 | H37: 157600 | I37: Available | J37: Paolo Lim | K37: Excellent, very light wear on corners | L37: 46251.497 | M37: 46270.519
A38: 51353147 | B38: Givenchy | C38: 4G Logo Slide Sandals | D38: Shoes | E38: Black Plague Leather | F38: 36600 | G38: 10000 | H38: 26600 | I38: Available | J38: Paolo Lim | K38: Good, visible wear on corners and handles. Size 38.5 Eu | L38: 46258.548 | M38: 46270.635
A39: 73192251 | B39: Hermes | C39: Constance To Go | D39: Crossbody | E39: Black Epsom Leather | F39: 395400 | G39: 47448 | H39: 347952 | I39: Available | J39: Rica Mercado | K39: Very good, light scratches on hardware | L39: 46255.429 | M39: 46270.649
A40: 21665851 | B40: Chanel | C40: Vintage Camera Bag | D40: Crossbody | E40: Cream Lambskin Leather | F40: 115000 | G40: 18000 | H40: 97000 | I40: Available | J40: Eduardo Zamora | K40: Pristine, no visible signs of use | L40: 46256.578 | M40: 46271.442
...

Sheet Closed Items
A1: Barcode | B1: Brand | C1: Model | D1: Category | E1: Price | F1: Outcome | G1: Consignor | H1: Intake At | I1: Closed At
A2: 34080571 | B2: Chanel | C2: Classic Double Flap Jumbo | D2: Shoulder Bag | E2: 313500 | F2: Closed – Failed authentication | G2: Rica Mercado | H2: 45446.488 | I2: 45458.66
A3: 06604859 | B3: Gucci | C3: Dionysus Mini Shoulder Bag | D3: Shoulder Bag | E3: 62500 | F3: Closed – Rejected | G3: Gabriel Garcia | H3: 45597.578 | I3: 45609.456
A4: 00970299 | B4: Hermes | C4: Mykonos Rubber Sandals | D4: Shoes | E4: 36600 | F4: Closed – Rejected | G4: Miguel Santos | H4: 45947.71 | I4: 45954.455
A5: 47592251 | B5: Chanel | C5: Boy Long Wallet | D5: Wallet | E5: 71100 | F5: Closed – Failed authentication | G5: Francis Aquino | H5: 45608.619 | I5: 45619.558
A6: 55692603 | B6: Fendi | C6: All | D6: Tote | E6: 59100 | F6: Closed – Rejected | G6: Paolo Laurel | H6: 46081.704 | I6: 46088.687
A7: 97499707 | B7: Hermes | C7: Mini Click Kelly Bracelet PM | D7: Jewelry | E7: 65900 | F7: Closed – Rejected | G7: Luis Andrada | H7: 45279.539 | I7: 45288.557
A8: 92745531 | B8: Louis Vuitton | C8: Alma PM | D8: Handbag | E8: 86800 | F8: Closed – Failed authentication | G8: Iñigo Soriano | H8: 45351.582 | I8: 45362.735
A9: 031200827 | B9: Loewe | C9: Compact Hammock Bag Large | D9: Handbag | E9: 83100 | F9: Closed – Failed authentication | G9: Yasmin Garcia | H9: 45710.438 | I9: 45713.729
A10: 70628411 | B10: Balenciaga | C10: Arena Giant Continental Wallet | D10: Wallet | E10: 34500 | F10: Closed – Failed authentication | G10: Paolo Laurel | H10: 46275.581 | I10: 46286.733
A11: 36154939 | B11: Christian Louboutin | C11: Louboutin Black Suede Hidden Platform Pumps Heels | D11: Shoes | E11: 22000 | F11: Closed – Failed authentication | G11: Carlo Madrigal | H11: 45680.544 | I11: 45690.678
A12: 69112123 | B12: Gucci | C12: Mini Tote Bag | D12: Tote | E12: 71100 | F12: Closed – Rejected | G12: Mika Manalo | H12: 45426.476 | I12: 45438.708
A13: 64390459 | B13: Saint Laurent | C13: LouLou Shoulder Bag | D13: Shoulder Bag | E13: 97200 | F13: Closed – Rejected | G13: Miguel Santos | H13: 46247.649 | I13: 46257.782
... A26: 32812859 | B26: Chanel | C26: CC Kelly Small | D26: Handbag | E26: 328200 | F26: Closed – Rejected | G26: Nicole Ayala | H26: 46195.713 | I26: 46202.681

Sheet Historical Sales
A1: Sale Date | B1: Brand | C1: Category | D1: Model | E1: Quantity | F1: Revenue | G1: Barcode | H1: Source
A2: 45202 | B2: Hermes | C2: Jewelry | D2: Rivale Double Tour Croc XS Bracelet Palladium Hardware | E2: 1 | F2: 46000 | G2: 98763835 | H2: Mock history from client catalog (price in markup-rule gap)
A3: 45225 | B3: Louis Vuitton | C3: Small Leather Goods | D3: Charms Card Holder | E3: 1 | F3: 36600 | G3: 23405115 | H3: Mock history from client catalog (price in markup-rule gap)
A4: 45231 | B4: Louis Vuitton | C4: Small Leather Goods | D4: Pochette Key Cles Pouch | E4: 1 | F4: 25100 | G4: 93491515 | H4: Mock history from client catalog (price in markup-rule gap)
A5: 45241 | B5: Gucci | C5: Crossbody | D5: GG Marmont Small Camera Bag | E5: 1 | F5: 45000 | G5: 69305659 | H5: Mock history from client catalog (price in markup-rule gap)
A6: 45256 | B6: Prada | C6: Small Leather Goods | D6: 1MC208 Portacarte Card Holder | E6: 1 | F6: 24000 | G6: 07188283 | H6: Mock history from client catalog (price in markup-rule gap)
A7: 45261 | B7: Gucci | C7: Clutch | D7: Supreme Floral Canvas Zip Clutch | E7: 1 | F7: 23000 | G7: 27057467 | H7: Mock history from client catalog (price in markup-rule gap)
A8: 45264 | B8: Prada | C8: Tote | D8: Daino Vitello Braided Handle Open Tote Bag | E8: 1 | F8: 41800 | G8: 24941115 | H8: Mock history from client catalog (price in markup-rule gap)
A9: 45274 | B9: Prada | C9: Crossbody | D9: Wallet On Chain | E9: 1 | F9: 36600 | G9: 72143675 | H9: Mock history from client catalog (price in markup-rule gap)
A10: 45277 | B10: Fendi | C10: Clothing | D10: Logo Print Two Color Checkered Hoodie | E10: 1 | F10: 49100 | G10: 05299515 | H10: Mock history from client catalog (price in markup-rule gap)
A11: 45284 | B11: Prada | C11: Handbag | D11: Promenade Bag Medium | E11: 1 | F11: 48100 | G11: 07597115 | H11: Mock history from client catalog (price in markup-rule gap)
A12: 45286 | B12: Chanel | C12: Small Leather Goods | D12: Flap Card Holder | E12: 1 | F12: 41800 | G12: 67459387 | H12: Mock history from client catalog (price in markup-rule gap)
A13: 45288 | B13: Prada | C13: Small Leather Goods | D13: x Universal Studios Frankenstein Heart | E13: 1 | F13: 47100 | G13: 95093563 | H13: Mock history from client catalog (price in markup-rule gap)
... A243: 46302 | B243: Loewe | C243: Shoes | D243: Cloudtilt All White Sneakers | E243: 1 | F243: 49100 | G243: 35631931 | H243: Mock history from client catalog (price in markup-rule gap)

Sheet Consignors
A1: Full Name | B1: Phone | C1: Email | D1: ID Type | E1: Items Consigned
A2: Miguel Santos | B2: 09930668581 | C2: miguel.santos@example.com | D2: passport | E2: 68
A3: Hannah Roxas | B3: 09243372480 | C3: hannah.roxas@example.com | D3: drivers_license | E3: 40
A4: Paolo Laurel | B4: 09469577591 | C4: paolo.laurel@example.com | D4: drivers_license | E4: 37
A5: Camille Lopez | B5: 09998226147 | C5: camille.lopez@example.com | D5: passport | E5: 27
A6: Lara Aquino | B6: 09355859675 | C6: lara.aquino@example.com | D6: passport | E6: 25
A7: Marco Aguilar | B7: 09825252642 | C7: marco.aguilar@example.com | D7: drivers_license | E7: 18
A8: Adrian Castillo | B8: 09829293402 | C8: adrian.castillo@example.com | D8: passport | E8: 15
A9: Miguel Javier | B9: 09103567620 | C9: miguel.javier@example.com | D9: drivers_license | E9: 15
A10: Paolo Lim | B10: 09947657215 | C10: paolo.lim@example.com | D10: umid | E10: 15
A11: Andrea Laurel | B11: 09717117215 | C11: andrea.laurel@example.com | D11: philsys_id | E11: 12
A12: Luis Andrada | B12: 09870586376 | C12: luis.andrada@example.com | D12: drivers_license | E12: 11
A13: Rica Mercado | B13: 09408107872 | C13: rica.mercado@example.com | D13: passport | E13: 10
... A279: Jasmine Domingo | B279: 09837409429 | C279: jasmine.domingo@example.com | D279: philsys_id | E279: 1

Sheet Catalog
A1: Barcode | B1: Vendor (original) | C1: Item Name (original) | D1: Price (original) | E1: Brand | F1: Category | G1: Model | H1: Colour / Material | I1: Hardware | J1: Date Code | K1: Size | L1: Microchip | M1: Used As
A2: 70428475 | B2: Chanel | C2: Chanel Boy Chevron Wallet on Chain in Peach Caviar Leather and Light Gold Hardware Microchip | D2: 187300 | E2: Chanel | F2: Crossbody | G2: Boy Chevron Wallet on Chain | H2: Peach Caviar Leather | I2: Light Gold | L2: Yes | M2: Sold (full record)
A3: 57010491 | B3: Chanel | C3: Chanel Classic Double Flap Medium in Black Caviar Leather and Gold Hardware Microchip | D3: 513000 | E3: Chanel | F3: Shoulder Bag | G3: Classic Double Flap Medium | H3: Black Caviar Leather | I3: Gold | L3: Yes | M3: Sold (full record)
A4: 64305211 | B4: Chanel | C4: Chanel CC Filigree Wallet on Chain in Beige and Black Caviar Leather and Gold Hardware Series 30 | D4: 199000 | E4: Chanel | F4: Crossbody | G4: CC Filigree Wallet on Chain | H4: Beige | I4: Gold | J4: Series 30 | M4: Sold (full record)
A5: 16201787 | B5: Chanel | C5: Chanel Turn Lock Wallet on Chain (WOC) in Black Caviar Leather Gold Hardware Microchip (AE****E4) | D5: 261000 | E5: Chanel | F5: Crossbody | G5: Turn Lock Wallet on Chain | H5: Black Caviar Leather | I5: Gold | L5: Yes | M5: Sold (full record)
A6: PMC-CONS-2026-00036 | B6: Chanel | C6: Chanel 25 Mini in Black Caviar Leather Shiny Gold Hardware Microchip (C5****81) | D6: 501800 | E6: Chanel | F6: Handbag | G6: 25 Mini | H6: Black Caviar Leather Shiny | I6: Shiny Gold | L6: Yes | M6: In stock – Available
A7: 39756347 | B7: Chanel | C7: Chanel Classic Double Flap Jumbo in Black Quilted Caviar Leather and Gold Hardware Series 27 | D7: 401000 | E7: Chanel | F7: Shoulder Bag | G7: Classic Double Flap Jumbo | H7: Black Quilted Caviar Leather | I7: Gold | J7: Series 27 | M7: Sold (full record)
A8: 53853499 | B8: Chanel | C8: Chanel Shopping Fever Tote Bag in Silver Metallic Caviar Leather and Silver Hardware Series 20 | D8: 86800 | E8: Chanel | F8: Tote | G8: Shopping Fever Tote Bag | H8: Silver Metallic Caviar Leather | I8: Silver | J8: Series 20 | M8: Closed – Rejected
A9: 57929787 | B9: Chanel | C9: Chanel Classic Double Flap in Dark Gray Caviar Leather Gold Hardware (Series 26) | D9: 391900 | E9: Chanel | F9: Shoulder Bag | G9: Classic Double Flap | H9: Dark Gray Caviar Leather | I9: Gold | J9: Series 26 | M9: Not used
A10: 18362939 | B10: Chanel | C10: Chanel Petite Shopping Tote Bag (PST) in Dark Beige Caviar Leather Gold Hardware (Series 8) | D10: 97200 | E10: Chanel | F10: Tote | G10: Petite Shopping Tote Bag | H10: Dark Beige Caviar Leather | I10: Gold | J10: Series 8 | M10: Sold (full record)
A11: 75838779 | B11: Chanel | C11: Chanel Classic Double Flap Jumbo in Red Quilted Caviar Leather and Silver Hardware Series 16 | D11: 335900 | E11: Chanel | F11: Shoulder Bag | G11: Classic Double Flap Jumbo | H11: Red Quilted Caviar Leather | I11: Silver | J11: Series 16 | M11: Sold (full record)
A12: 92724283 | B12: Chanel | C12: Chanel Paris Limited Edition Double Flap Bag Medium in Black Lambskin Leather Mix Hardware (Series 3) | D12: 210600 | E12: Chanel | F12: Shoulder Bag | G12: Paris Limited Edition Double Flap Bag Medium | H12: Black Lambskin Leather | I12: Mix | J12: Series 3 | M12: Sold (full record)
A13: 89119291 | B13: Chanel | C13: Chanel Classic Double Flap Bag Small in Black Caviar Leather Gold Hardware Microchip CX****KJ | D13: 602600 | E13: Chanel | F13: Shoulder Bag | G13: Classic Double Flap Bag Small | H13: Black Caviar Leather | I13: Gold | L13: Yes | M13: In stock – Available
A14: 14130235 | B14: Chanel | C14: Chanel Wallet on Chain (WOC) in Black Quilted Caviar Leather and Gold Hardware Series 29 | D14: 193200 | E14: Chanel | F14: Crossbody | G14: Wallet on Chain | H14: Black Quilted Caviar Leather | I14: Gold | J14: Series 29 | M14: Sold (full record)
A15: 18047547 | B15: Chanel | C15: Chanel Classic Mini Rectangular Flap Bag in Black Lambskin Leather Silver Hardware (Series 25) | D15: 277800 | E15: Chanel | F15: Shoulder Bag | G15: Classic Mini Rectangular Flap Bag | H15: Black Lambskin Leather | I15: Silver | J15: Series 25 | M15: Sold (full record)
A16: 18694971 | B16: Chanel | C16: Chanel CC You Flap Bag in Dark Brown Caviar Leather Shiny Gold Hardware (Microchip) | D16: 401000 | E16: Chanel | F16: Shoulder Bag | G16: CC You Flap Bag | H16: Dark Brown Caviar Leather Shiny | I16: Shiny Gold | L16: Yes | M16: Not used
A17: PMS-CONS-2026-00020 | B17: Chanel | C17: Chanel Classic Double Flap Medium in Black Caviar Leather Silver Hardware (Series 18) | D17: 434600 | E17: Chanel | F17: Shoulder Bag | G17: Classic Double Flap Medium | H17: Black Caviar Leather | I17: Silver | J17: Series 18 | M17: Sold (full record)
A18: 35468347 | B18: Chanel | C18: Chanel Wallet on Chain (WOC) in Black Quilted Caviar Leather and Gold Hardware Microchip | D18: 216200 | E18: Chanel | F18: Crossbody | G18: Wallet on Chain | H18: Black Quilted Caviar Leather | I18: Gold | L18: Yes | M18: Not used
A19: PMS-CONS-2026-00073 | B19: Chanel | C19: Chanel Classic Flap Card Holder in White Quilted Caviar Leather and Silver Hardware Series 30 | D19: 52300 | E19: Chanel | F19: Small Leather Goods | G19: Classic Flap Card Holder | H19: White Quilted Caviar Leather | I19: Silver | J19: Series 30 | M19: Sold (full record)
A20: 87910203 | B20: Chanel | C20: Chanel Business Affinity Flap Bag Medium in Red Caviar Leather and Gold Hardware Series 28 | D20: 246300 | E20: Chanel | F20: Shoulder Bag | G20: Business Affinity Flap Bag Medium | H20: Red Caviar Leather | I20: Gold | J20: Series 28 | M20: In stock – Available
A21: 58059579 | B21: Chanel | C21: Chanel Wallet on Chain (WOC) in Black Caviar Leather Silver Hardware Microchip (X9****PL) | D21: 244200 | E21: Chanel | F21: Crossbody | G21: Wallet on Chain | H21: Black Caviar Leather | I21: Silver | L21: Yes | M21: Sold (full record)
A22: 53566523 | B22: Chanel | C22: Chanel Envelope Flap Bag in White Chevron Calfskin Leather and Gold Hardware Series 27 | D22: 144300 | E22: Chanel | F22: Shoulder Bag | G22: Envelope Flap Bag | H22: White Chevron Calfskin Leather | I22: Gold | J22: Series 27 | M22: Sold (full record)
A23: 06365499 | B23: Chanel | C23: Chanel Classic Flap Card Holder in Black Quilted Calfskin Leather and Silver Hardware Series 22 | D23: 38500 | E23: Chanel | F23: Small Leather Goods | G23: Classic Flap Card Holder | H23: Black Quilted Calfskin Leather | I23: Silver | J23: Series 22 | M23: Historical sale (markup gap)
A24: 74417723 | B24: Chanel | C24: Chanel Deauville Tote Bag in Vibrant Yellow Mixed Fibers and Light Gold Hardware Microchip | D24: 175600 | E24: Chanel | F24: Tote | G24: Deauville Tote Bag | H24: Vibrant Yellow Mixed Fibers | I24: Light Gold | L24: Yes | M24: Sold (full record)
A25: 50660923 | B25: Chanel | C25: Chanel Le Boy New Medium in Black Chevron Lambskin Leather and Ruthenium Hardware Series 22 | D25: 277800 | E25: Chanel | F25: Shoulder Bag | G25: Le Boy New Medium | H25: Black Chevron Lambskin Leather | I25: Ruthenium | J25: Series 22 | M25: Sold (full record)
A26: 14550587 | B26: Chanel | C26: Chanel Boy Wallet On Chain in Black Quilted Caviar Leather and Aged Gold Hardware Microchip | D26: 175600 | E26: Chanel | F26: Crossbody | G26: Boy Wallet On Chain | H26: Black Quilted Caviar Leather | I26: Aged Gold | L26: Yes | M26: Sold (full record)
A27: 43233595 | B27: Chanel | C27: Chanel Deauville Bowling Bag Small in Pink Canvas Silver Hardware (Series 20) | D27: 123400 | E27: Chanel | F27: Handbag | G27: Deauville Bowling Bag Small | H27: Pink Canvas | I27: Silver | J27: Series 20 | M27: Sold (full record)
A28: 211543611 | B28: Chanel | C28: Chanel Turn Lock Wallet on Chain (WOC) in Black Caviar Leather Gold Hardware Microchip (P3****83) | D28: 266600 | E28: Chanel | F28: Crossbody | G28: Turn Lock Wallet on Chain | H28: Black Caviar Leather | I28: Gold | L28: Yes | M28: Sold (full record)
A29: 56165691 | B29: Chanel | C29: Chanel Classic Wallet on Chain (WOC) in Black Caviar Leather Silver Hardware Microchip (HJ****5J) | D29: 244200 | E29: Chanel | F29: Crossbody | G29: Classic Wallet on Chain | H29: Black Caviar Leather | I29: Silver | L29: Yes | M29: Sold (full record)
A30: 95962939 | B30: Chanel | C30: Chanel Wallet on Chain (WOC) in Black Caviar Leather and Silver Hardware Microchip (HC****E0) | D30: 244200 | E30: Chanel | F30: Crossbody | G30: Wallet on Chain | H30: Black Caviar Leather | I30: Silver | L30: Yes | M30: Sold (full record)
A31: 60598331 | B31: Chanel | C31: Chanel Classic Wallet on Chain (WOC) in Black Caviar Leather Silver Hardware Series (29****17) | D31: 227400 | E31: Chanel | F31: Crossbody | G31: Classic Wallet on Chain | H31: Black Caviar Leather | I31: Silver | M31: Sold (full record)
A32: 67340603 | B32: Chanel | C32: Chanel Classic Wallet on Chain (WOC) in Black Caviar Leather Gold Hardware Microchip (L6****54) | D32: 233000 | E32: Chanel | F32: Crossbody | G32: Classic Wallet on Chain | H32: Black Caviar Leather | I32: Gold | L32: Yes | M32: Sold (full record)
A33: 89115451 | B33: Chanel | C33: Chanel Classic Wallet on Chain (WOC) in Black Caviar Leather Gold Hardware Microchip (X1***CC) | D33: 238600 | E33: Chanel | F33: Crossbody | G33: Classic Wallet on Chain | H33: Black Caviar Leather | I33: Gold | L33: Yes | M33: Not used
A34: 031509307 | B34: Chanel | C34: Chanel Classic Wallet on Chain (WOC) in Black Caviar Leather Silver Hardware (Series 30****85) | D34: 221800 | E34: Chanel | F34: Crossbody | G34: Classic Wallet on Chain | H34: Black Caviar Leather | I34: Silver | J34: Series 30 | M34: Sold (full record)
A35: 96333371 | B35: Chanel | C35: Chanel 19 Flap Bag Medium in Black Lambskin Leather Mix Hardware (Microchip) | D35: 333800 | E35: Chanel | F35: Shoulder Bag | G35: 19 Flap Bag Medium | H35: Black Lambskin Leather | I35: Mix | L35: Yes | M35: Sold (full record)
A36: 57142843 | B36: Chanel | C36: Chanel Business Affinity Small in Caramel Caviar Leather Light Gold Hardware (Series 30) | D36: 291100 | E36: Chanel | F36: Handbag | G36: Business Affinity Small | H36: Caramel Caviar Leather Light | I36: Light Gold | J36: Series 30 | M36: Sold (full record)
A37: 78368571 | B37: Chanel | C37: Chanel Matelassé Camera Bag in Yellow Calfskin Leather and Gold Hardware Series 26 | D37: 144300 | E37: Chanel | F37: Crossbody | G37: Matelassé Camera Bag | H37: Yellow Calfskin Leather | I37: Gold | J37: Series 26 | M37: Not used
A38: 54465851 | B38: Chanel | C38: Chanel Classic Wallet on Chain (WOC) in Black Caviar Leather in Gold Hardware Microchip (HK****3L) | D38: 238600 | E38: Chanel | F38: Crossbody | G38: Classic Wallet on Chain | H38: Black Caviar Leather in | I38: Gold | L38: Yes | M38: Sold (full record)
A39: 24901179 | B39: Chanel | C39: Chanel Le Boy Small in Black Chevron Lambskin Leather and Silver Hardware Series 22 | D39: 240700 | E39: Chanel | F39: Shoulder Bag | G39: Le Boy Small | H39: Black Chevron Lambskin Leather | I39: Silver | J39: Series 22 | M39: Not used
A40: 95737659 | B40: Chanel | C40: Chanel Medallion Tote Bag in Black Quilted Patent Leather Series 6 | D40: 97000 | E40: Chanel | F40: Tote | G40: Medallion Tote Bag | H40: Black Quilted Patent Leather | J40: Series 6 | M40: Sold (full record)
...
